[2024-12-08T05:19:41.529+0000] {local_task_job_runner.py:123} INFO - ::group::Pre task execution logs
[2024-12-08T05:19:41.585+0000] {taskinstance.py:2613} INFO - Dependencies all met for dep_context=non-requeueable deps ti=<TaskInstance: fetch_and_store_amazon_books.insert_book_data scheduled__2024-10-29T00:00:00+00:00 [queued]>
[2024-12-08T05:19:41.634+0000] {taskinstance.py:2613} INFO - Dependencies all met for dep_context=requeueable deps ti=<TaskInstance: fetch_and_store_amazon_books.insert_book_data scheduled__2024-10-29T00:00:00+00:00 [queued]>
[2024-12-08T05:19:41.635+0000] {taskinstance.py:2866} INFO - Starting attempt 1 of 2
[2024-12-08T05:19:41.715+0000] {taskinstance.py:2889} INFO - Executing <Task(PythonOperator): insert_book_data> on 2024-10-29 00:00:00+00:00
[2024-12-08T05:19:41.746+0000] {warnings.py:112} WARNING - /home/***/.local/lib/python3.12/site-packages/***/task/task_runner/standard_task_runner.py:70: DeprecationWarning: This process (pid=1869) is multi-threaded, use of fork() may lead to deadlocks in the child.
  pid = os.fork()

[2024-12-08T05:19:41.760+0000] {standard_task_runner.py:72} INFO - Started process 1921 to run task
[2024-12-08T05:19:41.783+0000] {standard_task_runner.py:104} INFO - Running: ['***', 'tasks', 'run', 'fetch_and_store_amazon_books', 'insert_book_data', 'scheduled__2024-10-29T00:00:00+00:00', '--job-id', '413', '--raw', '--subdir', 'DAGS_FOLDER/app.py', '--cfg-path', '/tmp/tmpyxz9wpkh']
[2024-12-08T05:19:41.785+0000] {standard_task_runner.py:105} INFO - Job 413: Subtask insert_book_data
[2024-12-08T05:19:41.917+0000] {task_command.py:467} INFO - Running <TaskInstance: fetch_and_store_amazon_books.insert_book_data scheduled__2024-10-29T00:00:00+00:00 [running]> on host 2b2f4f7613f2
[2024-12-08T05:19:42.214+0000] {taskinstance.py:3132} INFO - Exporting env vars: AIRFLOW_CTX_DAG_OWNER='***' AIRFLOW_CTX_DAG_ID='fetch_and_store_amazon_books' AIRFLOW_CTX_TASK_ID='insert_book_data' AIRFLOW_CTX_EXECUTION_DATE='2024-10-29T00:00:00+00:00' AIRFLOW_CTX_TRY_NUMBER='1' AIRFLOW_CTX_DAG_RUN_ID='scheduled__2024-10-29T00:00:00+00:00'
[2024-12-08T05:19:42.219+0000] {logging_mixin.py:190} INFO - Task instance is in running state
[2024-12-08T05:19:42.221+0000] {logging_mixin.py:190} INFO -  Previous state of the Task instance: queued
[2024-12-08T05:19:42.226+0000] {logging_mixin.py:190} INFO - Current task name:insert_book_data state:running start_date:2024-12-08 05:19:41.593314+00:00
[2024-12-08T05:19:42.227+0000] {logging_mixin.py:190} INFO - Dag name:fetch_and_store_amazon_books and current dag run status:running
[2024-12-08T05:19:42.228+0000] {taskinstance.py:731} INFO - ::endgroup::
[2024-12-08T05:19:42.283+0000] {taskinstance.py:3311} ERROR - Task failed with exception
Traceback (most recent call last):
  File "/home/airflow/.local/lib/python3.12/site-packages/airflow/models/taskinstance.py", line 767, in _execute_task
    result = _execute_callable(context=context, **execute_callable_kwargs)
             ^^^^^^^^^^^^^^^^^^^^^^^^^^^^^^^^^^^^^^^^^^^^^^^^^^^^^^^^^^^^^
  File "/home/airflow/.local/lib/python3.12/site-packages/airflow/models/taskinstance.py", line 733, in _execute_callable
    return ExecutionCallableRunner(
           ^^^^^^^^^^^^^^^^^^^^^^^^
  File "/home/airflow/.local/lib/python3.12/site-packages/airflow/utils/operator_helpers.py", line 252, in run
    return self.func(*args, **kwargs)
           ^^^^^^^^^^^^^^^^^^^^^^^^^^
  File "/home/airflow/.local/lib/python3.12/site-packages/airflow/models/baseoperator.py", line 417, in wrapper
    return func(self, *args, **kwargs)
           ^^^^^^^^^^^^^^^^^^^^^^^^^^^
  File "/home/airflow/.local/lib/python3.12/site-packages/airflow/operators/python.py", line 238, in execute
    return_value = self.execute_callable()
                   ^^^^^^^^^^^^^^^^^^^^^^^
  File "/home/airflow/.local/lib/python3.12/site-packages/airflow/operators/python.py", line 256, in execute_callable
    return runner.run(*self.op_args, **self.op_kwargs)
           ^^^^^^^^^^^^^^^^^^^^^^^^^^^^^^^^^^^^^^^^^^^
  File "/home/airflow/.local/lib/python3.12/site-packages/airflow/utils/operator_helpers.py", line 252, in run
    return self.func(*args, **kwargs)
           ^^^^^^^^^^^^^^^^^^^^^^^^^^
  File "/opt/airflow/dags/app.py", line 94, in insert_book_data_into_postgres
    raise ValueError("No book data found")
ValueError: No book data found
[2024-12-08T05:19:42.329+0000] {logging_mixin.py:190} INFO - Task instance in failure state
[2024-12-08T05:19:42.330+0000] {logging_mixin.py:190} INFO - Task start:2024-12-08 05:19:41.593314+00:00 end:2024-12-08 05:19:42.328333+00:00 duration:0.735019
[2024-12-08T05:19:42.331+0000] {logging_mixin.py:190} INFO - Task:<Task(PythonOperator): insert_book_data> dag:<DAG: fetch_and_store_amazon_books> dagrun:<DagRun fetch_and_store_amazon_books @ 2024-10-29 00:00:00+00:00: scheduled__2024-10-29T00:00:00+00:00, state:running, queued_at: 2024-12-08 05:19:23.483189+00:00. externally triggered: False>
[2024-12-08T05:19:42.333+0000] {logging_mixin.py:190} INFO - Failure caused by No book data found
[2024-12-08T05:19:42.334+0000] {taskinstance.py:1225} INFO - Marking task as UP_FOR_RETRY. dag_id=fetch_and_store_amazon_books, task_id=insert_book_data, run_id=scheduled__2024-10-29T00:00:00+00:00, execution_date=20241029T000000, start_date=20241208T051941, end_date=20241208T051942
[2024-12-08T05:19:42.416+0000] {taskinstance.py:340} INFO - ::group::Post task execution logs
[2024-12-08T05:19:42.418+0000] {standard_task_runner.py:124} ERROR - Failed to execute job 413 for task insert_book_data (No book data found; 1921)
Traceback (most recent call last):
  File "/home/airflow/.local/lib/python3.12/site-packages/airflow/task/task_runner/standard_task_runner.py", line 117, in _start_by_fork
    ret = args.func(args, dag=self.dag)
          ^^^^^^^^^^^^^^^^^^^^^^^^^^^^^
  File "/home/airflow/.local/lib/python3.12/site-packages/airflow/cli/cli_config.py", line 49, in command
    return func(*args, **kwargs)
           ^^^^^^^^^^^^^^^^^^^^^
  File "/home/airflow/.local/lib/python3.12/site-packages/airflow/utils/cli.py", line 116, in wrapper
    return f(*args, **kwargs)
           ^^^^^^^^^^^^^^^^^^
  File "/home/airflow/.local/lib/python3.12/site-packages/airflow/cli/commands/task_command.py", line 483, in task_run
    task_return_code = _run_task_by_selected_method(args, _dag, ti)
                       ^^^^^^^^^^^^^^^^^^^^^^^^^^^^^^^^^^^^^^^^^^^^
  File "/home/airflow/.local/lib/python3.12/site-packages/airflow/cli/commands/task_command.py", line 256, in _run_task_by_selected_method
    return _run_raw_task(args, ti)
           ^^^^^^^^^^^^^^^^^^^^^^^
  File "/home/airflow/.local/lib/python3.12/site-packages/airflow/cli/commands/task_command.py", line 341, in _run_raw_task
    return ti._run_raw_task(
           ^^^^^^^^^^^^^^^^^
  File "/home/airflow/.local/lib/python3.12/site-packages/airflow/utils/session.py", line 97, in wrapper
    return func(*args, session=session, **kwargs)
           ^^^^^^^^^^^^^^^^^^^^^^^^^^^^^^^^^^^^^^
  File "/home/airflow/.local/lib/python3.12/site-packages/airflow/models/taskinstance.py", line 3005, in _run_raw_task
    return _run_raw_task(
           ^^^^^^^^^^^^^^
  File "/home/airflow/.local/lib/python3.12/site-packages/airflow/models/taskinstance.py", line 273, in _run_raw_task
    TaskInstance._execute_task_with_callbacks(
  File "/home/airflow/.local/lib/python3.12/site-packages/airflow/models/taskinstance.py", line 3159, in _execute_task_with_callbacks
    result = self._execute_task(context, task_orig)
             ^^^^^^^^^^^^^^^^^^^^^^^^^^^^^^^^^^^^^^
  File "/home/airflow/.local/lib/python3.12/site-packages/airflow/models/taskinstance.py", line 3183, in _execute_task
    return _execute_task(self, context, task_orig)
           ^^^^^^^^^^^^^^^^^^^^^^^^^^^^^^^^^^^^^^^
  File "/home/airflow/.local/lib/python3.12/site-packages/airflow/models/taskinstance.py", line 767, in _execute_task
    result = _execute_callable(context=context, **execute_callable_kwargs)
             ^^^^^^^^^^^^^^^^^^^^^^^^^^^^^^^^^^^^^^^^^^^^^^^^^^^^^^^^^^^^^
  File "/home/airflow/.local/lib/python3.12/site-packages/airflow/models/taskinstance.py", line 733, in _execute_callable
    return ExecutionCallableRunner(
           ^^^^^^^^^^^^^^^^^^^^^^^^
  File "/home/airflow/.local/lib/python3.12/site-packages/airflow/utils/operator_helpers.py", line 252, in run
    return self.func(*args, **kwargs)
           ^^^^^^^^^^^^^^^^^^^^^^^^^^
  File "/home/airflow/.local/lib/python3.12/site-packages/airflow/models/baseoperator.py", line 417, in wrapper
    return func(self, *args, **kwargs)
           ^^^^^^^^^^^^^^^^^^^^^^^^^^^
  File "/home/airflow/.local/lib/python3.12/site-packages/airflow/operators/python.py", line 238, in execute
    return_value = self.execute_callable()
                   ^^^^^^^^^^^^^^^^^^^^^^^
  File "/home/airflow/.local/lib/python3.12/site-packages/airflow/operators/python.py", line 256, in execute_callable
    return runner.run(*self.op_args, **self.op_kwargs)
           ^^^^^^^^^^^^^^^^^^^^^^^^^^^^^^^^^^^^^^^^^^^
  File "/home/airflow/.local/lib/python3.12/site-packages/airflow/utils/operator_helpers.py", line 252, in run
    return self.func(*args, **kwargs)
           ^^^^^^^^^^^^^^^^^^^^^^^^^^
  File "/opt/airflow/dags/app.py", line 94, in insert_book_data_into_postgres
    raise ValueError("No book data found")
ValueError: No book data found
[2024-12-08T05:19:42.503+0000] {local_task_job_runner.py:266} INFO - Task exited with return code 1
[2024-12-08T05:19:42.538+0000] {local_task_job_runner.py:245} INFO - ::endgroup::
